Workbook
Name COMPANY_NAME: FrontPage!$A$1:$M$40
Name DETAIL: 'Detail Data'!$A$1:$G$40
Name FrontPage: FrontPage!$A$1:$G$40
Name FUNDAMENTALS: FrontPage!$H$2:$M$40
Name IQ_CH: 110000
Name IQ_CQ: 5000
Name IQ_CY: 10000
Name IQ_DAILY: 500000
Name IQ_FH: 100000
Name IQ_FQ: 500
Name IQ_FY: 1000
Name IQ_LTM: 2000
Name IQ_MONTH: 15000
Name IQ_NTM: 6000
Name IQ_WEEK: 50000
Name IQ_YTD: 3000

Sheet FrontPage
A1: The Hershey Company (HSY)
A2: Share Symbol: | C2: HSY | E2: Exchange Traded: | F2: NYSE | H2: FUNDAMENTALS
A3: Recent price: (US$) | C3: 159.46 | E3: Student: | F3: Chris Lester | H3: Most Recent Qtr Report | I3: 2QFY26 | K3: Market Capitalization (M $$) | M3: =C3*'Detail Data'!E9 -> 32434.164
A4: Date: | C4: 46299 | E4: TXST Email: | F4: wjs65@txstate.edu | H4: Last Full Fiscal Year | I4: 2025 | K4: Enterprise Value (M $$) | M4: =M3+'Detail Data'!E34-'Detail Data'!E28 -> 35676.364
C5: Index | E5: Earnings (GAAP) | F5: E (% Chg)-cagr | G5: Multiple | H5: Profitability | K5: Balance Sheet
A6: S&P 500 (t-1) | C6: 6715.35 | H6: Gross Margin (%) | I6: ='Detail Data'!E23 -> 0.41118204 | K6: Cash - M $$ | M6: ='Detail Data'!E28 -> 1451.5
A7: S&P 500 (Current) | C7: 7722.72 | E7: =C7/C6-1 -> 0.15001005 | F7: 358.17 | G7: =C7/F7 -> 21.561605 | H7: Avg Gross Margin (3 yrs) | I7: =AVERAGE('Detail Data'!C23,'Detail Data'!D23,'Detail Data'!E23) -> 0.40662173 | K7: Cash per Share - $$ | M7: =M6/'Detail Data'!E9 -> 7.1361849
A8: S&P 500 (t+1) | C8: 8000 | E8: =F8/F7-1 -> 0.0051093056 | F8: 360 | G8: =C8/F8 -> 22.222222 | H8: Net Margin (%) | I8: ='Detail Data'!E25 -> 0.13910462 | K8: Free Cash Flow to the firm- M $$ | M8: ='Detail Data'!D41 -> 0
A9: S&P 500 (t+2) | C9: 8700 | E9: =F9/F8-1 -> 0.11111111 | F9: 400 | G9: =C9/F9 -> 21.75 | H9: Net Margin (3 Yrs) | I9: =AVERAGE('Detail Data'!C25,'Detail Data'!D25,'Detail Data'!E25) -> 0.13764295 | K9: FCFF per Share - SS | M9: =M8/'Detail Data'!E9 -> 0
A10: Company Description | E10: CATALYSTS (RECENT DEVELOPMENTS) | H10: EBITDA Margin (%) | I10: ='Detail Data'!E26 -> 0.24682633 | K10: Net Debt - M $$ | M10: ='Detail Data'!E34 -> 4693.7
A11: Founded in 1894, Hershey is the largest producer of quality chocolate in North America and a leading U.S. snack maker. Brands include Hershey's, Reese's, Kisses, Jolly Rancher and Kit Kat (U.S.) and salty snacks (SkinnyPop, Dot's Homestyle Pretzels). FY2025 net sales were $11.69 billion; about 19,600 employees. Source: FY2025 Form 10-K (S1). | E11: 1) Q3 2026 results, expected Oct 22, 2026: management expects the year's strongest earnings growth as peak cocoa costs are lapped (S3). 2) Cocoa is down more than 70% from late-2024 highs; the relief reaches margins with a lag through hedges and inventory (S6). 3) FY2026 guidance raised in July: net sales growth of 4.5 to 5.0% and adjusted EPS of $8.36 to $8.52 (S2). | H11: Avg EBITDA Margin (%) | I11: =AVERAGE('Detail Data'!C26,'Detail Data'!D26,'Detail Data'!E26) -> 0.23751538 | K11: Net Debt/FCF - % | M11: ='DCF 1-Pager'!C69/'Detail Data'!D41 -> #DIV/0!
H12: Outlook | K12: Valuation Models | L12: Multiple | M12: Price Target
H13: Revenue Growth (LTM) | I13: =('Detail Data'!E5/'Detail Data'!D5)-1 -> 0.051648051 | K13: P/E (Current - LTM) | L13: ='Detail Data'!E12 -> 2.6376745 | M13: =L13*'Detail Data'!E7 -> 159.46
H14: Revenue Growth (Fwd 12month) | I14: ='Detail Data'!F5/'Detail Data'!E5-1 -> 0.024966454 | K14: P/E (Fwd 12 Months) | L14: ='Detail Data'!F12 -> 2.5734252 | M14: =L13*'Detail Data'!F7 -> 163.44115
A15: Revenue Segments | E15: WHAT'S UNIQUE (MOAT) | H15: Revenue Growth (Fwd 24month) | I15: =(('Detail Data'!G5/'Detail Data'!E5)^(1/2))-1 -> 0.025511209 | K15: P/E (Fwd 24 Months) | L15: ='Detail Data'!G12 -> 2.5080741 | M15: =L13*'Detail Data'!G7 -> 167.69981
A16: FY2025 net sales (S1): North America Confectionery $9,479.7M (81%); North America Salty Snacks $1,271.3M (11%); International $941.6M (8%). | E16: 1) Brands with pricing power: Hershey's, Reese's and Kisses carried roughly 14% price increases in 2026 and net sales still grew (S3, S4). 2) Scale: the largest producer of quality chocolate in North America, with the manufacturing and retail distribution that come with it (S1). | H16: EPS Growth (LTM) | I16: ='Detail Data'!E7/'Detail Data'!D7-1 -> 12.92967 | K16: MC/Rev (Current - LTM) | L16: ='Detail Data'!E11 -> 2.6376745 | M16: =('Detail Data'!E11*'Detail Data'!E5)/'Detail Data'!E9 -> 159.46 | N16: Mult = (pr*sh)/rev
H17: EPS Growth (Fwd 12Month) | I17: ='Detail Data'!F7/'Detail Data'!E7-1 -> 0.024966454 | K17: MC/Rev (Fwd 12Month) | L17: ='Detail Data'!F11 -> 2.5734252 | M17: =('Detail Data'!E11*'Detail Data'!F5)/'Detail Data'!F9 -> 163.44115 | N17: (Mult*Rev)/Sh
H18: EPS Growth (Fwd 24Month) | I18: =(('Detail Data'!G7/'Detail Data'!E7)^(1/2))-1 -> 0.025511209 | K18: MC/Rev (Fwd 24Month) | L18: ='Detail Data'!G11 -> 2.5080741 | M18: =('Detail Data'!E11*'Detail Data'!G5)/'Detail Data'!G9 -> 167.69981 | N18: Mult = (EV / EBITDA)
A19: How Does the Company Make Money (Unit Economics)?? | E19: Main Strengths | H19: Capital Allocation | K19: EV / EBITDA (LTM) | L19: ='Detail Data'!E13 -> 11.501964 | M19: =(('Detail Data'!E13*'Detail Data'!E21)-'Detail Data'!E34+'Detail Data'!E28)/'Detail Data'!E9 -> 155.69031 | N19: Mult = (MC + Debt - Cash) / EBITDA
A20: Hershey sells branded chocolate, sweets and snacks to retailers and distributors. Revenue is volume times net price, and price is the lever: Q2 2026 net sales rose 6.6% on roughly 14% pricing while confectionery volume fell about 10% (S3, S4). The swing cost is cocoa, then sugar, dairy and packaging: gross margin fell from 47.3% in FY2024 to 33.5% in FY2025 as cocoa peaked (S1). Reinvestment is light: capex was 3.9% of sales in FY2025, below D&A, so operating profit converts to cash ($2.28B operating cash flow) and is returned as dividends ($1.09B) (S1). | E20: 1) Cash generation: $2.28B of operating cash flow in FY2025, a trough-margin year (S1). | H20: ROE | I20: ='Detail Data'!E35/AVERAGE('Detail Data'!E30,'Detail Data'!D30) -> 0.34483455 | K20: EV/EBITDA (Fwd 12Months) | L20: ='Detail Data'!F13 -> 10.28629 | M20: =(('Detail Data'!E13*'Detail Data'!F21)+'Detail Data'!F28-'Detail Data'!F34)/'Detail Data'!F9 -> 177.20681 | N20: Mult = ((Pr * SH)+ Debt - Cash) / EBITDA
E21: 2) Low capital intensity: capex 3.9% of sales, below D&A (S1). | H21: Avg ROE (3 Yrs) | I21: ='Detail Data'!E17/AVERAGE('Detail Data'!C35,'Detail Data'!D35,'Detail Data'!E35) -> 0.36311979 | K21: EV/EBITDA (Fwd 24Months) | L21: ='Detail Data'!G13 -> 9.8220725 | M21: =(('Detail Data'!E13*'Detail Data'!G21)+'Detail Data'!G28-'Detail Data'!G34)/'Detail Data'!G9 -> 187.95221 | N21: ((Mult*EBITDA)+Cash-Debt)/Sh
E22: 3) Pricing power: Q2 2026 net sales up 6.6% on about 14% pricing (S3, S4). | H22: Asset Turnover | I22: ='Detail Data'!E40/AVERAGE('Detail Data'!E30,'Detail Data'!D30,'Detail Data'!C30) -> 0.032514168 | N22: Mult = EV / FCF
E23: Main Risks | H23: Avg AT (3 yrs) | I23: ='Detail Data'!E17/'Detail Data'!E35 -> 0.35783022 | N23: Mult = ((Pr*sh)+Debt-Cash)/ FCF
A24: Main Peers / Comps | E24: 1) Volume: confectionery volume fell about 10% in Q2 2026 as prices rose (S4). | H24: Fincl Lev | I24: =AVERAGE('Detail Data'!D30,'Detail Data'!E30)/AVERAGE('Detail Data'!D35,'Detail Data'!E35) -> 2.9441011 | N24: Pr = ((Mult * FCF)+Cash-Debt) / Sh
A25: 1) Mondelez (MDLZ) | B25: 3) Lindt & Spruengli (LISN) | E25: 2) Cocoa: one input took operating margin from 25.9% to 12.3% in a year (S1, S6). | H25: Avg Fincl Lev (3 Yrs) | I25: =AVERAGE('Detail Data'!C30,'Detail Data'!D30,'Detail Data'!E30)/AVERAGE('Detail Data'!C35,'Detail Data'!D35,'Detail Data'!E35) -> 2.8780331
A26: 2) Nestle (NESN) | B26: 4) General Mills (GIS) | E26: 3) Concentration: North America Confectionery is 81% of net sales (S1).
A27: Share Price (USD) - 5 yrs
H28: Capital Intensity | K28: Normalized Multiples
H29: CAPEX/Revenues - % | I29: ='Detail Data'!E40/'Detail Data'!E5 -> 0.035847599 | K29: (P/E) / EGr (Fwd 1Yr) - x | M29: ='Detail Data'!E12/(1+FrontPage!I16) -> 0.18935656
H30: Avg CAPEX/Rev (3 yrs) - % | I30: =AVERAGE('Detail Data'!E40,'Detail Data'!D40,'Detail Data'!C40)/AVERAGE('Detail Data'!E5,'Detail Data'!D5,'Detail Data'!C5) -> 0.042660991 | K30: (MC/Rev) / RevGr (Fwd 1Yr) - x | M30: ='Detail Data'!E11/(1+FrontPage!I13) -> 2.5081342
K31: (EV/EBITDA) / EBITDA Gr (Fwd 1Yr) - x | M31: ='Detail Data'!E13/(('Detail Data'!E21/'Detail Data'!D21)) -> 7.3716252
I41: 0.791

Sheet Detail Data
A2: SUMMARY DATA (M$) | C2: =(YEAR(FrontPage!$C$4)-2)&"A" -> 2024A | D2: =YEAR(FrontPage!$C$4)-1&"A" -> 2025A | E2: =(YEAR(FrontPage!$C$4))&"F" -> 2026F | F2: =(YEAR(FrontPage!$C$4)+1)&"F" -> 2027F | G2: =(YEAR(FrontPage!$C$4)+2)&"F" -> 2028F
A3: Market Capitalization (M$) | C3: =C9*FrontPage!$C3 -> 32450.11 | D3: =D9*FrontPage!C3 -> 32434.164 | E3: =E9*FrontPage!C3 -> 32434.164 | F3: =F9*FrontPage!C3 -> 32434.164 | G3: =G9*FrontPage!C3 -> 32434.164
A4: Enterprise Value (M$) | C4: =C3+C34-C28 -> 34909.61 | D4: =D3+D34-D28 -> 36189.464 | E4: =E3+E34-E28 -> 35676.364 | F4: =F3+F34-F28 -> 35425.664 | G4: =G3+G34-G28 -> 35084.964
A5: =CONCATENATE("Revenue (t) - Current FY") -> Revenue (t) - Current FY | C5: 11202.3 | D5: 11692.6 | E5: 12296.5 | F5: 12603.5 | G5: 12931.9
A6: =CONCATENATE("Revenue (t-1) - Previous FY") -> Revenue (t-1) - Previous FY | C6: 11165 | D6: 11202.3 | E6: =D5 -> 11692.6 | F6: =E5 -> 12296.5 | G6: =F5 -> 12603.5
A7: =CONCATENATE("FD EPS (t) - Current FY") -> FD EPS (t) - Current FY | C7: 10.92 | D7: 4.34 | E7: =E5/E9 -> 60.454769 | F7: =F5/F9 -> 61.96411 | G7: =G5/G9 -> 63.578663
A8: =CONCATENATE("FD EPS (t-1) - Previous FY") -> FD EPS (t-1) - Previous FY | C8: 9.06 | D8: 10.92 | E8: =D7 -> 4.34 | F8: =E7 -> 60.454769 | G8: =F7 -> 61.96411
A9: FD Shares outstanding (M) | C9: 203.5 | D9: 203.4 | E9: =D9 -> 203.4 | F9: =E9 -> 203.4 | G9: =F9 -> 203.4
A10: VALUATION MULTIPLES | C10: =C2 -> 2024A | D10: =D2 -> 2025A | E10: =E2 -> 2026F | F10: =F2 -> 2027F | G10: =G2 -> 2028F
A11: Mkt Cap/Revenue | C11: =(FrontPage!$C3*C9)/C5 -> 2.8967364 | D11: =(FrontPage!C3*D9)/D5 -> 2.7739052 | E11: =E3/E5 -> 2.6376745 | F11: =F3/F5 -> 2.5734252 | G11: =G3/G5 -> 2.5080741
A12: P/E | C12: =FrontPage!$C3/C7 -> 14.602564 | D12: =FrontPage!C3/D7 -> 36.741935 | E12: =FrontPage!C3/E7 -> 2.6376745 | F12: =FrontPage!$C3/F7 -> 2.5734252 | G12: =FrontPage!$C3/G7 -> 2.5080741
A13: EV/EBITDA | C13: =$C4/C21 -> 10.409903 | D13: =$C4/D21 -> 17.94654 | E13: =$C4/E21 -> 11.501964 | F13: =$C4/F21 -> 10.28629 | G13: =$C4/G21 -> 9.8220725
A14: INCOME STATEMENT (Millions $$) | C14: =C2 -> 2024A | D14: =D2 -> 2025A | E14: =E2 -> 2026F | F14: =F2 -> 2027F | G14: =G2 -> 2028F
A15: Cost of Sales | C15: 5901.4 | D15: 7769.9 | E15: 7240.4 | F15: 7074.5 | G15: 7220.6
A16: EBIT (aka Pre-Tax Income / Oper Inc) | C16: 2898.2 | D16: 1441.5 | E16: =E21-E38 -> 2546.6905 | F16: =F21-F38 -> 2835.4753 | G16: =G21-G38 -> 2985.2384
A17: Net Income (t) - Current FY | C17: 2221.2 | D17: 883.3 | E17: 1710.5 | F17: 1988.8 | G17: 2108.4
A18: =CONCATENATE("Net Income (t-1) - Previous FY") -> Net Income (t-1) - Previous FY | C18: 1861.8 | D18: 2221.2 | E18: =D17 -> 883.3 | F18: =E17 -> 1710.5 | G18: =F17 -> 1988.8
A19: Interest Expense | C19: 165.7 | D19: 190.2 | E19: ='WACC calculation'!$D$13*'Detail Data'!E34 -> 0 | F19: ='WACC calculation'!$D$13*'Detail Data'!F34 -> 0 | G19: ='WACC calculation'!$D$13*'Detail Data'!G34 -> 0
A20: Income Taxes | C20: 252.7 | D20: 330.9 | E20: 597.7 | F20: 689.8 | G20: 707.8
A21: EBITDA | C21: 3353.5 | D21: 1945.2 | E21: 3035.1 | F21: 3393.8 | G21: 3554.2
A22: MARGINS (%) | C22: =C2 -> 2024A | D22: =D2 -> 2025A | E22: =E2 -> 2026F | F22: =F2 -> 2027F | G22: =G2 -> 2028F
A23: Gross Margin | C23: =(C5-C15)/C5 -> 0.47319747 | D23: =(D5-D15)/D5 -> 0.33548569 | E23: =(E5-E15)/E5 -> 0.41118204 | F23: =(F5-F15)/F5 -> 0.43868767 | G23: =(G5-G15)/G5 -> 0.44164431
A24: EBIT Margin (aka Pre-Tax Margin) | C24: =C16/C5 -> 0.25871473 | D24: =D16/D5 -> 0.1232831 | E24: =E16/E5 -> 0.20710694 | F24: =F16/F5 -> 0.22497523 | G24: =G16/G5 -> 0.23084298
A25: Net Income Margin (%) | C25: =C17/C5 -> 0.19828071 | D25: =D17/D5 -> 0.075543506 | E25: =E17/E5 -> 0.13910462 | F25: =F17/F5 -> 0.15779744 | G25: =G17/G5 -> 0.16303869
A26: EBITDA Margin | C26: =C21/C5 -> 0.29935817 | D26: =D21/D5 -> 0.16636163 | E26: =E21/E5 -> 0.24682633 | F26: =F21/F5 -> 0.26927441 | G26: =G21/G5 -> 0.27483974
A27: BALANCE SHEET (Millions $$) | C27: =C2 -> 2024A | D27: =D2 -> 2025A | E27: =E2 -> 2026F | F27: =F2 -> 2027F | G27: =G2 -> 2028F
A28: CASH & MKTBLE SECURITIES | C28: 730.7 | D28: 925.9 | E28: 1451.5 | F28: 1635.5 | G28: 1909.5
A29: Cash & Mktble Sec per Share | C29: =C28/C9 -> 3.5906634 | D29: =D28/D9 -> 4.5521141 | E29: =E28/E9 -> 7.1361849 | F29: =F28/F9 -> 8.0408063 | G29: =G28/G9 -> 9.3879056
A30: Total Assets | C30: 12946.9 | D30: 13741.3 | E30: 13983.3 | F30: 14093.3 | G30: 14406
A31: Current Assets | C31: 3759.5 | D31: 3588.9 | E31: 4123 | F31: 4242 | G31: 4541
A32: Current Liabilities | C32: 3929.5 | D32: 3011.9 | E32: 3261.5 | F32: 3192.5 | G32: 3195.5
A33: Net Working Capital | C33: =C31-C32 -> -170 | D33: =D31-D32 -> 577 | E33: =E31-E32 -> 861.5 | F33: =F31-F32 -> 1049.5 | G33: =G31-G32 -> 1345.5
A34: Long Term Debt | C34: 3190.2 | D34: 4681.2 | E34: 4693.7 | F34: 4627 | G34: 4560.3
A35: Equity | C35: 4714.7 | D35: 4636.8 | E35: 4780.2 | F35: 5081.8 | G35: 5441.8
A36: CASH FLOW STATEMENT (Millions $$) | C36: =C2 -> 2024A | D36: =D2 -> 2025A | E36: =E2 -> 2026F | F36: =F2 -> 2027F | G36: =G2 -> 2028F
A37: NOPAT | E37: =E16*(1-E20/E16) -> 1948.9905 | F37: =F16*(1-F20/F16) -> 2145.6753 | G37: =G16*(1-G20/G16) -> 2277.4384
A38: Depreciation + Amortization | C38: 455.3 | D38: 503.7 | E38: =D38/D40*E40 -> 488.4095 | F38: =E38/E40*F40 -> 558.32475 | G38: =F38/F40*G40 -> 568.96161
A39: Change in NWC | E39: =E33-D33 -> 284.5 | F39: =F33-E33 -> 188 | G39: =G33-F33 -> 296
A40: Capital Expenditures (PPE) | C40: 605.9 | D40: 454.6 | E40: 440.8 | F40: 503.9 | G40: 513.5
A41: Free Cash Flow to the Firm | B41: EBIT(1-t)+D&A-Capex-change in NWC | E41: =E37+E38-E39-E40 -> 1712.1 | F41: =F37+F38-F39-F40 -> 2012.1 | G41: =G37+G38-G39-G40 -> 2036.9
...

Sheet DCF 1-Pager
B2: Discounted Cash Flow Valuation
B3: $ and shares in thousands, except for per share data | L3: Summary: | P3: Relative Valuation
B4: Company name | D4: =FrontPage!A1 -> The Hershey Company (HSY) | M4: Terminal Value Assumption | R4: Times | S4: Product | T4: Adjusted | U4: Shares O/S | V4: Value Estimate
B5: Ticker symbol | D5: =FrontPage!C2 -> HSY | M5: Perpetual Growth | N5: Multiple | P5: P/E ratio | Q5: =AVERAGE('Relative Valuation'!D4:D6) -> #DIV/0! | R5: =D21-D24 -> 901.48828 | S5: =R5*Q5 -> #DIV/0! | T5: =S5 -> #DIV/0! | U5: =I65 -> 207154.37 | V5: =T5/U5 -> #DIV/0!
B6: Most recent fiscal year end | D6: 46022 | F6: Discount rate (WACC) | H6: ='WACC calculation'!D16 -> 0 | P6: EV/EBITDA | Q6: =AVERAGE('Relative Valuation'!C4:C6) -> #DIV/0! | R6: =D19 -> 1945.2 | S6: =R6*Q6 -> #DIV/0! | T6: =S6-C69 -> #DIV/0! | U6: =U5 -> 207154.37 | V6: =T6/U6 -> #DIV/0!
B7: End of first fiscal year | D7: =EOMONTH(D6,12) -> 46387 | F7: Share price (Public Co) | H7: =FrontPage!C3 -> 159.46 | L7: FCFF | M7: =C77 -> -0.018128027 | N7: =D77 -> -0.018128027 | P7: EV/Sales | Q7: =AVERAGE('Relative Valuation'!E4:E6) -> #DIV/0! | R7: =D17 -> 11692.6 | S7: =R7*Q7 -> #DIV/0! | T7: =S7-C69 -> #DIV/0! | U7: =U6 -> 207154.37 | V7: =T7/U7 -> #DIV/0!
B8: Most recent quarter end date | D8: 46203 | F8: Share price date | H8: =D9 -> 46299 | L8: FCFE | M8: =C108 -> 0 | N8: =D108 -> 0
B9: Valuation date | D9: =FrontPage!C4 -> 46299 | F9: Midyear adjustment? | H9: 0
B10: Portion of year 1 cash flows in forecast | D10: =YEARFRAC(D9,D7) -> 0.24166667
B12: Free cash flow to the firm (FCFF)
B13: Unlevered Free Cash Flows
D14: Actual | E14: Forecasts
B15: Fiscal year ended | D15: ='Detail Data'!D2 -> 2025A | E15: ='Detail Data'!E2 -> 2026F | F15: ='Detail Data'!F2 -> 2027F | G15: ='Detail Data'!G2 -> 2028F
B17: Revenue | D17: ='Detail Data'!D5 -> 11692.6 | E17: ='Detail Data'!E5 -> 12296.5 | F17: ='Detail Data'!F5 -> 12603.5 | G17: ='Detail Data'!G5 -> 12931.9
B18: % growth | E18: =E17/D17-1 -> 0.051648051 | F18: =F17/E17-1 -> 0.024966454 | G18: =G17/F17-1 -> 0.026056254
B19: EBITDA | D19: ='Detail Data'!D21 -> 1945.2 | E19: ='Detail Data'!E21 -> 3035.1 | F19: ='Detail Data'!F21 -> 3393.8 | G19: ='Detail Data'!G21 -> 3554.2
B20: % margin | D20: =D19/D17 -> 0.16636163 | E20: =E19/E17 -> 0.24682633 | F20: =F19/F17 -> 0.26927441 | G20: =G19/G17 -> 0.27483974
B21: EBIT | D21: ='Detail Data'!D16 -> 1441.5 | E21: ='Detail Data'!E16 -> 2546.6905 | F21: ='Detail Data'!F16 -> 2835.4753 | G21: ='Detail Data'!G16 -> 2985.2384
B22: % margin | D22: =D21/D17 -> 0.1232831 | E22: =E21/E17 -> 0.20710694 | F22: =F21/F17 -> 0.22497523 | G22: =G21/G17 -> 0.23084298
B24: Tax on EBIT | D24: =D25*D21 -> 540.01172 | E24: ='Detail Data'!E20 -> 597.7 | F24: ='Detail Data'!F20 -> 689.8 | G24: ='Detail Data'!G20 -> 707.8
B25: Tax rate | D25: ='Detail Data'!D20/'Detail Data'!D17 -> 0.37461791 | E25: =E24/E21 -> 0.23469676 | F25: =F24/F21 -> 0.24327491 | G25: =G24/G21 -> 0.23709999
B26: NOPAT (aka EBIAT) | D26: =D21-D24 -> 901.48828 | E26: =E21-E24 -> 1948.9905 | F26: =F21-F24 -> 2145.6753 | G26: =G21-G24 -> 2277.4384
B28: Depreciation & amortization | D28: ='Detail Data'!D38 -> 503.7 | E28: ='Detail Data'!E38 -> 488.4095 | F28: ='Detail Data'!F38 -> 558.32475 | G28: ='Detail Data'!G38 -> 568.96161
B29: Changes in net working capital | D29: =C36-D36 -> -747 | E29: =D36-E36 -> -284.5 | F29: =E36-F36 -> -188 | G29: =F36-G36 -> -296
B30: Capital expenditures | D30: =-'Detail Data'!D40 -> -454.6 | E30: =-'Detail Data'!E40 -> -440.8 | F30: =-'Detail Data'!F40 -> -503.9 | G30: =-'Detail Data'!G40 -> -513.5
B31: as % of revenue | D31: =FrontPage!I30 -> 0.042660991 | E31: =D31 -> 0.042660991 | F31: =E31 -> 0.042660991 | G31: =F31 -> 0.042660991
B33: Free cash flow to the firm
B34: Unlevered free cash flows (UFCF)
B36: Net working capital (WC Assets - WC liabilities) | C36: ='Detail Data'!C33 -> -170 | D36: ='Detail Data'!D33 -> 577 | E36: ='Detail Data'!E33 -> 861.5 | F36: ='Detail Data'!F33 -> 1049.5 | G36: ='Detail Data'!G33 -> 1345.5
B37: as % of revenue | D37: =D36/D17 -> 0.049347451 | E37: =E36/E17 -> 0.070060586 | F37: =F36/F17 -> 0.08327052 | G37: =G36/G17 -> 0.10404504
B39: ="Present value of UFCF on "&TEXT(D9,"mmm dd, yyyy")&" valuation date" -> Present value of UFCF on Oct 04, 2026 valuation date
D40: Val date | E40: Yr 1 - Stub | F40: Year 2 | G40: Year 3
B41: Date for discounting cash flows | D41: =D9 -> 46299 | E41: =DATE(YEAR($D$6)+1,12,31) -> 46387 | F41: =DATE(YEAR($D$6)+2,12,31) -> 46752 | G41: =DATE(YEAR($D$6)+3,12,31) -> 47118
B42: Unlevered free cash flows (UFCF) stub adjusted | C42: =D10 -> 0.24166667 | E42: =(E26+E28+E29+E30)*C42 -> 413.7575 | F42: =F26+F28+F29+F30 -> 2012.1 | G42: =G26+G28+G29+G30 -> 2036.9 | K42: <-Stub year counts first year cash flows starting at the valuation date
B43: Present value of of unlevered free cash flows | E43: =E42/(1+$H$6)^((E41-$D$41)/365) -> 413.7575 | F43: =F42/(1+$H$6)^((F41-$D$41)/365) -> 2012.1 | G43: =G42/(1+$H$6)^((G41-$D$41)/365) -> 2036.9
B45: Terminal value - growth in perpetuity approach | E45: Terminal value - EBITDA multiple approach
B46: Long term growth rate | E46: Terminal year EBITDA
B47: =YEAR(G41)&" FCF x (1+g)" -> 2028 FCF x (1+g) | D47: Estimate for 2029 FCF | E47: EBITDA multiple
B48: ="Terminal value in "&YEAR(D6)+3 -> Terminal value in 2028 | E48: ="Terminal value in "&YEAR(G41) -> Terminal value in 2028 | L48: PV(0) = CF(1)/(r-g)
B49: Present value of terminal value | E49: Present value of terminal value
...

Sheet Relative Valuation
B2: Company | C2: EV/EBITDA | D2: P/E | E2: EV/Sales

Sheet WACC calculation
C2: Dollar Amount | D2: Weight
B3: Market Value of Equity | C3: ='Detail Data'!D3 -> 32434.164 | D3: =C3/C5 -> 0.87387433
B4: Book Value of Debt | C4: ='Detail Data'!D34 -> 4681.2 | D4: =C4/C5 -> 0.12612567
B5: Total Market Value (EV) | C5: =C3+C4 -> 37115.364
C7: Cost of Equity:
C8: Rm - Rf (Market Risk Premium) | F8: R(j)=Rf+Beta(j)*(Rm-Rf)
C9: Rf
C10: Beta
C11: Cost of Equity
C13: Cost of Debt
C14: Tax rate
C16: WACC | D16: =D3*D11+D4*D13*(1-D14) -> 0
B20: Hamada's formula
B21: industry average beta
B22: D/E for industry
B23: t for industry
B25: Industry unlevered beta
B27: Relever for my company
B28: Company D/E
B29: t for company
B30: Beta estimate Hamada's
